Traceback (most recent call last):
  File "/Users/igorlimarochaazevedo/Programming/DSP/dsp-174/venv/lib/python3.12/site-packages/jupyter_cache/executors/utils.py", line 58, in single_nb_execution
    executenb(
  File "/Users/igorlimarochaazevedo/Programming/DSP/dsp-174/venv/lib/python3.12/site-packages/nbclient/client.py", line 1314, in execute
    return NotebookClient(nb=nb, resources=resources, km=km, **kwargs).execute()
           ^^^^^^^^^^^^^^^^^^^^^^^^^^^^^^^^^^^^^^^^^^^^^^^^^^^^^^^^^^^^^^^^^^^^^
  File "/Users/igorlimarochaazevedo/Programming/DSP/dsp-174/venv/lib/python3.12/site-packages/jupyter_core/utils/__init__.py", line 165, in wrapped
    return loop.run_until_complete(inner)
           ^^^^^^^^^^^^^^^^^^^^^^^^^^^^^^
  File "/opt/homebrew/Cellar/python@3.12/3.12.2_1/Frameworks/Python.framework/Versions/3.12/lib/python3.12/asyncio/base_events.py", line 685, in run_until_complete
    return future.result()
           ^^^^^^^^^^^^^^^
  File "/Users/igorlimarochaazevedo/Programming/DSP/dsp-174/venv/lib/python3.12/site-packages/nbclient/client.py", line 709, in async_execute
    await self.async_execute_cell(
  File "/Users/igorlimarochaazevedo/Programming/DSP/dsp-174/venv/lib/python3.12/site-packages/nbclient/client.py", line 1062, in async_execute_cell
    await self._check_raise_for_error(cell, cell_index, exec_reply)
  File "/Users/igorlimarochaazevedo/Programming/DSP/dsp-174/venv/lib/python3.12/site-packages/nbclient/client.py", line 918, in _check_raise_for_error
    raise CellExecutionError.from_cell_and_msg(cell, exec_reply_content)
nbclient.exceptions.CellExecutionError: An error occurred while executing the following cell:
------------------
import numpy as np
import matplotlib.pyplot as plt
from scipy.signal import convolve2d

# Sample image (5x5 for simplicity)
image = np.array([[10, 10, 10, 10, 10],
                  [10, 20, 20, 20, 10],
                  [10, 20, 30, 20, 10],
                  [10, 20, 20, 20, 10],
                  [10, 10, 10, 10, 10]])

# Define the kernel
kernel = np.array([[-1, -1, -1],
                   [-1,  8, -1],
                   [-1, -1, -1]])

# Perform convolution
conv_image = convolve2d(image, kernel, mode='same')

# Plotting
fig, axs = plt.subplots(1, 2, figsize=(10, 5))

# Original image
axs[0].imshow(image, cmap='gray')
axs[0].set_title('Original Image')
axs[0].axis('off')

# Convolved image
axs[1].imshow(conv_image, cmap='gray')
axs[1].set_title('Convolved Image')
axs[1].axis('off')

plt.tight_layout()
plt.show()

------------------


[0;31m---------------------------------------------------------------------------[0m
[0;31mModuleNotFoundError[0m                       Traceback (most recent call last)
Cell [0;32mIn[3], line 3[0m
[1;32m      1[0m [38;5;28;01mimport[39;00m [38;5;21;01mnumpy[39;00m [38;5;28;01mas[39;00m [38;5;21;01mnp[39;00m
[1;32m      2[0m [38;5;28;01mimport[39;00m [38;5;21;01mmatplotlib[39;00m[38;5;21;01m.[39;00m[38;5;21;01mpyplot[39;00m [38;5;28;01mas[39;00m [38;5;21;01mplt[39;00m
[0;32m----> 3[0m [38;5;28;01mfrom[39;00m [38;5;21;01mscipy[39;00m[38;5;21;01m.[39;00m[38;5;21;01msignal[39;00m [38;5;28;01mimport[39;00m convolve2d
[1;32m      5[0m [38;5;66;03m# Sample image (5x5 for simplicity)[39;00m
[1;32m      6[0m image [38;5;241m=[39m np[38;5;241m.[39marray([[[38;5;241m10[39m, [38;5;241m10[39m, [38;5;241m10[39m, [38;5;241m10[39m, [38;5;241m10[39m],
[1;32m      7[0m                   [[38;5;241m10[39m, [38;5;241m20[39m, [38;5;241m20[39m, [38;5;241m20[39m, [38;5;241m10[39m],
[1;32m      8[0m                   [[38;5;241m10[39m, [38;5;241m20[39m, [38;5;241m30[39m, [38;5;241m20[39m, [38;5;241m10[39m],
[1;32m      9[0m                   [[38;5;241m10[39m, [38;5;241m20[39m, [38;5;241m20[39m, [38;5;241m20[39m, [38;5;241m10[39m],
[1;32m     10[0m                   [[38;5;241m10[39m, [38;5;241m10[39m, [38;5;241m10[39m, [38;5;241m10[39m, [38;5;241m10[39m]])

[0;31mModuleNotFoundError[0m: No module named 'scipy'

